<?xml version="1.0"?>

<robot name="my_robot" xmlns:xacro="http://www.ros.org/wiki/xacro">

  <xacro:include filename="$(find my_robot)/urdf/my_robot.gazebo" />

  <!-- Robot Footprint -->
  <link name="robot_footprint" />

  <joint name="robot_footprint_joint" type="fixed">
    <origin xyz="0 0 0" rpy="0 0 0" />
    <parent link="robot_footprint" />
    <child link="chassis" />
  </joint>

  <!-- Chassis -->
  <link name="chassis">
    <pose>0 0 0.1 0 0 0</pose>

    <inertial>
      <mass value="15.0" />
      <origin xyz="0.0 0 0" rpy="0 0 0" />
      <inertia
        ixx="0.1" ixy="0" ixz="0"
        iyy="0.1" iyz="0"
        izz="0.1"
      />
    </inertial>

    <!-- Main Box Collision -->
    <collision name="collision">
      <origin xyz="0 0 0" rpy="0 0 0" />
      <geometry>
        <box size="0.4 0.2 0.1" />
      </geometry>
    </collision>

    <!-- Main Box Visual -->
    <visual name="chassis_visual">
      <origin xyz="0 0 0" rpy="0 0 0" />
      <geometry>
        <box size="0.4 0.2 0.1" />
      </geometry>
      <material name="blue">
        <color rgba="0.2 0.2 1.0 1.0" />
      </material>
    </visual>

    <!-- Back Caster -->
    <collision name="back_caster_collision">
      <origin xyz="-0.15 0 -0.05" rpy="0 0 0" />
      <geometry>
        <sphere radius="0.0499" />
      </geometry>
    </collision>

    <visual name="back_caster_visual">
      <origin xyz="-0.15 0 -0.05" rpy="0 0 0" />
      <geometry>
        <sphere radius="0.05" />
      </geometry>
    </visual>

    <!-- Front Caster -->
    <collision name="front_caster_collision">
      <origin xyz="0.15 0 -0.05" rpy="0 0 0" />
      <geometry>
        <sphere radius="0.0499" />
      </geometry>
    </collision>

    <visual name="front_caster_visual">
      <origin xyz="0.15 0 -0.05" rpy="0 0 0" />
      <geometry>
        <sphere radius="0.05" />
      </geometry>
    </visual>

  </link>

  <!-- Left Wheel Link -->
  <link name="left_wheel">

    <inertial>
      <mass value="5.0" />
      <origin xyz="0 0 0" rpy="0 1.5707 1.5707" />
      <inertia
        ixx="0.006" ixy="0" ixz="0"
        iyy="0.006" iyz="0"
        izz="0.025"
      />
    </inertial>

    <collision>
      <origin xyz="0 0 0" rpy="0 1.5707 1.5707" />
      <geometry>
        <cylinder radius="0.1" length="0.05" />
      </geometry>
      <!-- Add surface friction to both wheel collisions -->
      <!-- It will stabilize flickering of the wheels -->
      <surface>
        <friction>
          <ode>
            <mu>1.0</mu>
            <mu2>1.0</mu2>
          </ode>
        </friction>
      </surface> 
    </collision>

    <visual>
      <origin xyz="0 0 0" rpy="0 1.5707 1.5707" />
      <geometry>
        <cylinder radius="0.1" length="0.05" />
      </geometry>
      <material name="green">
        <color rgba="0 1 0 1" />
      </material>
    </visual>

  </link>

  <!-- Right Wheel Link -->
  <link name="right_wheel">

    <inertial>
      <mass value="5.0" />
      <origin xyz="0 0 0" rpy="0 1.5707 1.5707" />
      <inertia
        ixx="0.006" ixy="0" ixz="0"
        iyy="0.006" iyz="0"
        izz="0.025"
      />
    </inertial>

    <collision>
      <origin xyz="0 0 0" rpy="0 1.5707 1.5707" />
      <geometry>
        <cylinder radius="0.1" length="0.05" />
      </geometry>
      <!-- Add surface friction to both wheel collisions -->
      <!-- It will stabilize flickering of the wheels -->
      <surface>
        <friction>
          <ode>
            <mu>1.0</mu>
            <mu2>1.0</mu2>
          </ode>
        </friction>
      </surface> 
    </collision>

    <visual>
      <origin xyz="0 0 0" rpy="0 1.5707 1.5707" />
      <geometry>
        <cylinder radius="0.1" length="0.05" />
      </geometry>
      <material name="green">
        <color rgba="0 1 0 1" />
      </material>
    </visual>

  </link>

  <!-- Left Wheel Joint -->
  <joint name="left_wheel_joint" type="continuous">
    <parent link="chassis" />
    <child link="left_wheel" />
    <origin xyz="0 ±0.15 -0.05" rpy="0 0 0" />
    <axis xyz="0 1 0" />
    <limit effort="10.0" velocity="10.0" />
    <dynamics damping="0.1" friction="0.0" />
  </joint>

  <!-- Right Wheel Joint -->
  <joint name="right_wheel_joint" type="continuous">
    <parent link="chassis" />
    <child link="right_wheel" />
    <origin xyz="0 ±0.15 -0.05" rpy="0 0 0" />
    <axis xyz="0 1 0" />
    <limit effort="10.0" velocity="10.0" />
    <dynamics damping="0.1" friction="0.0" />
  </joint>

  <!-- Camera Link -->
  <link name="camera">

    <inertial>
      <mass value="0.1" />
      <origin xyz="0 0 0" rpy="0 0 0" />
      <inertia
        ixx="1e-6" ixy="0" ixz="0"
        iyy="1e-6" iyz="0"
        izz="1e-6"
      />
    </inertial>

    <collision>
      <origin xyz="0 0 0" rpy="0 0 0" />
      <geometry>
        <box size="0.05 0.05 0.05" />
      </geometry>
    </collision>

    <visual>
      <origin xyz="0 0 0" rpy="0 0 0" />
      <geometry>
        <box size="0.05 0.05 0.05" />
      </geometry>
      <material name="red">
        <color rgba="1 0 0 1" />
      </material>
    </visual>

  </link>

  <!-- Camera Joint -->
  <joint name="camera_joint" type="fixed">
    <parent link="chassis" />
    <child link="camera" />
    <origin xyz="0.2 0 0" rpy="0 0 0" />
    <axis xyz="0 1 0" />
  </joint>

  <!-- Hokuyo Lidar Link -->
  <link name="hokuyo">

    <inertial>
      <mass value="1e-5" />
      <origin xyz="0 0 0" rpy="0 0 0" />
      <inertia
        ixx="1e-6" ixy="0" ixz="0"
        iyy="1e-6" iyz="0"
        izz="1e-6"
      />
    </inertial>

    <!-- Collision geometry -->
    <collision>
      <origin xyz="0 0 0" rpy="0 0 0" />
      <geometry>
        <box size="0.1 0.1 0.1" />
      </geometry>
    </collision>

    <!-- Visual geometry -->
    <visual>
      <origin xyz="0 0 0" rpy="0 0 0" />
      <geometry>
        <mesh filename="package://my_robot/meshes/hokuyo.dae" />
      </geometry>
      <material name="yellow">
        <color rgba="1 1 0 1" />
      </material>
    </visual>

  </link>

  <!-- Hokuyo Lidar Joint -->
  <joint name="hokuyo_joint" type="fixed">
    <parent link="chassis" />
    <child link="hokuyo" />
    <origin xyz="0.15 0 0.1" rpy="0 0 0" />
    <axis xyz="0 1 0" />
  </joint>

</robot>

